<?xml version="1.0" ?>
<robot name="robot" xmlns:xacro="http://www.ros.org/wiki/xacro">

<xacro:include filename="$(find robot_description)/urdf/materials.xacro" />
<xacro:include filename="$(find robot_description)/urdf/robot.trans" />
<xacro:include filename="$(find robot_description)/urdf/robot.gazebo" />
<link name="base_link">
  <inertial>
    <origin xyz="-0.0012338585101228624 -0.0010949155991113232 0.21978904084516823" rpy="0 0 0"/>
    <mass value="10.573359294297559"/>
    <inertia ixx="0.878048" iyy="0.219776" izz="1.097119" ixy="-0.0" iyz="0.0" ixz="0.0"/>
  </inertial>
  <visual>
    <origin xyz="0 0 0" rpy="0 0 0"/>
    <geometry>
      <mesh filename="package://robot_description/meshes/base_link.stl" scale="0.001 0.001 0.001"/>
    </geometry>
    <material name="abs_white"/>
  </visual>
  <collision>
    <origin xyz="0 0 0" rpy="0 0 0"/>
    <geometry>
      <mesh filename="package://robot_description/meshes/base_link.stl" scale="0.001 0.001 0.001"/>
    </geometry>
  </collision>
</link>

<link name="base_top_1">
  <inertial>
    <origin xyz="1.4148987467917616e-07 8.440088874257963e-08 0.020000040845168182" rpy="0 0 0"/>
    <mass value="7.920000000000001"/>
    <inertia ixx="0.166056" iyy="0.060456" izz="0.2244" ixy="-0.0" iyz="0.0" ixz="0.0"/>
  </inertial>
  <visual>
    <origin xyz="0.001234 0.001095 -0.229789" rpy="0 0 0"/>
    <geometry>
      <mesh filename="package://robot_description/meshes/base_top_1.stl" scale="0.001 0.001 0.001"/>
    </geometry>
    <material name="paek_beige"/>
  </visual>
  <collision>
    <origin xyz="0.001234 0.001095 -0.229789" rpy="0 0 0"/>
    <geometry>
      <mesh filename="package://robot_description/meshes/base_top_1.stl" scale="0.001 0.001 0.001"/>
    </geometry>
  </collision>
</link>

<link name="camera_1">
  <inertial>
    <origin xyz="1.414898741741548e-07 -0.024999915599112743 0.010000040845168368" rpy="0 0 0"/>
    <mass value="0.040229154316593144"/>
    <inertia ixx="3e-06" iyy="1.7e-05" izz="1.7e-05" ixy="-0.0" iyz="0.0" ixz="0.0"/>
  </inertial>
  <visual>
    <origin xyz="0.001234 -0.248905 -0.269789" rpy="0 0 0"/>
    <geometry>
      <mesh filename="package://robot_description/meshes/camera_1.stl" scale="0.001 0.001 0.001"/>
    </geometry>
    <material name="plastic_glossy_black"/>
  </visual>
  <collision>
    <origin xyz="0.001234 -0.248905 -0.269789" rpy="0 0 0"/>
    <geometry>
      <mesh filename="package://robot_description/meshes/camera_1.stl" scale="0.001 0.001 0.001"/>
    </geometry>
  </collision>
</link>

<link name="lidar_1">
  <inertial>
    <origin xyz="1.4148987538217285e-07 0.07500008440088982 0.22500004084516777" rpy="0 0 0"/>
    <mass value="0.26554311904467726"/>
    <inertia ixx="0.000137" iyy="0.000137" izz="0.000163" ixy="-0.0" iyz="0.0" ixz="0.0"/>
  </inertial>
  <visual>
    <origin xyz="0.001234 0.251095 -0.269789" rpy="0 0 0"/>
    <geometry>
      <mesh filename="package://robot_description/meshes/lidar_1.stl" scale="0.001 0.001 0.001"/>
    </geometry>
    <material name="plastic_matte_red"/>
  </visual>
  <collision>
    <origin xyz="0.001234 0.251095 -0.269789" rpy="0 0 0"/>
    <geometry>
      <mesh filename="package://robot_description/meshes/lidar_1.stl" scale="0.001 0.001 0.001"/>
    </geometry>
  </collision>
</link>

<link name="azimuth_v1_1">
  <inertial>
    <origin xyz="0.039326933307061385 8.440088494765519e-08 -0.07395386702602089" rpy="0 0 0"/>
    <mass value="0.27902894572056625"/>
    <inertia ixx="0.000476" iyy="0.000607" izz="0.000165" ixy="-0.0" iyz="0.0" ixz="0.000177"/>
  </inertial>
  <visual>
    <origin xyz="0.231234 -0.458905 -0.229789" rpy="0 0 0"/>
    <geometry>
      <mesh filename="package://robot_description/meshes/azimuth_v1_1.stl" scale="0.001 0.001 0.001"/>
    </geometry>
    <material name="aluminum_satin"/>
  </visual>
  <collision>
    <origin xyz="0.231234 -0.458905 -0.229789" rpy="0 0 0"/>
    <geometry>
      <mesh filename="package://robot_description/meshes/azimuth_v1_1.stl" scale="0.001 0.001 0.001"/>
    </geometry>
  </collision>
</link>

<link name="azimuth_v1_2">
  <inertial>
    <origin xyz="0.03932693330706474 8.440089260819406e-08 -0.07395386702602194" rpy="0 0 0"/>
    <mass value="0.27902894572056625"/>
    <inertia ixx="0.000476" iyy="0.000607" izz="0.000165" ixy="-0.0" iyz="0.0" ixz="0.000177"/>
  </inertial>
  <visual>
    <origin xyz="0.231234 0.461095 -0.229789" rpy="0 0 0"/>
    <geometry>
      <mesh filename="package://robot_description/meshes/azimuth_v1_2.stl" scale="0.001 0.001 0.001"/>
    </geometry>
    <material name="aluminum_satin"/>
  </visual>
  <collision>
    <origin xyz="0.231234 0.461095 -0.229789" rpy="0 0 0"/>
    <geometry>
      <mesh filename="package://robot_description/meshes/azimuth_v1_2.stl" scale="0.001 0.001 0.001"/>
    </geometry>
  </collision>
</link>

<link name="azimuth_v1_3">
  <inertial>
    <origin xyz="-0.03932665032731664 8.440088422601022e-08 -0.073953867026021" rpy="0 0 0"/>
    <mass value="0.27902894572056625"/>
    <inertia ixx="0.000476" iyy="0.000607" izz="0.000165" ixy="-0.0" iyz="0.0" ixz="-0.000177"/>
  </inertial>
  <visual>
    <origin xyz="-0.228766 -0.458905 -0.229789" rpy="0 0 0"/>
    <geometry>
      <mesh filename="package://robot_description/meshes/azimuth_v1_3.stl" scale="0.001 0.001 0.001"/>
    </geometry>
    <material name="aluminum_satin"/>
  </visual>
  <collision>
    <origin xyz="-0.228766 -0.458905 -0.229789" rpy="0 0 0"/>
    <geometry>
      <mesh filename="package://robot_description/meshes/azimuth_v1_3.stl" scale="0.001 0.001 0.001"/>
    </geometry>
  </collision>
</link>

<link name="azimuth_v1_4">
  <inertial>
    <origin xyz="-0.039326650327313334 8.440089216410485e-08 -0.07395386702602208" rpy="0 0 0"/>
    <mass value="0.27902894572056625"/>
    <inertia ixx="0.000476" iyy="0.000607" izz="0.000165" ixy="-0.0" iyz="0.0" ixz="-0.000177"/>
  </inertial>
  <visual>
    <origin xyz="-0.228766 0.461095 -0.229789" rpy="0 0 0"/>
    <geometry>
      <mesh filename="package://robot_description/meshes/azimuth_v1_4.stl" scale="0.001 0.001 0.001"/>
    </geometry>
    <material name="aluminum_satin"/>
  </visual>
  <collision>
    <origin xyz="-0.228766 0.461095 -0.229789" rpy="0 0 0"/>
    <geometry>
      <mesh filename="package://robot_description/meshes/azimuth_v1_4.stl" scale="0.001 0.001 0.001"/>
    </geometry>
  </collision>
</link>

<link name="wheel_v1_1">
  <inertial>
    <origin xyz="-0.04953933219433282 8.440087373440264e-08 1.039909556105334e-07" rpy="0 0 0"/>
    <mass value="0.6661433062671792"/>
    <inertia ixx="0.001849" iyy="0.001024" izz="0.001024" ixy="0.0" iyz="0.0" ixz="-0.0"/>
  </inertial>
  <visual>
    <origin xyz="0.181234 0.461095 -0.07904" rpy="0 0 0"/>
    <geometry>
      <mesh filename="package://robot_description/meshes/wheel_v1_1.stl" scale="0.001 0.001 0.001"/>
    </geometry>
    <material name="rubber_soft"/>
  </visual>
  <collision>
    <origin xyz="0.181234 0.461095 -0.07904" rpy="0 0 0"/>
    <geometry>
      <mesh filename="package://robot_description/meshes/wheel_v1_1.stl" scale="0.001 0.001 0.001"/>
    </geometry>
  </collision>
</link>

<link name="wheel_v1_2">
  <inertial>
    <origin xyz="-0.04953933219433643 8.440086635141952e-08 1.0399095665136748e-07" rpy="0 0 0"/>
    <mass value="0.6661433062671792"/>
    <inertia ixx="0.001849" iyy="0.001024" izz="0.001024" ixy="0.0" iyz="0.0" ixz="-0.0"/>
  </inertial>
  <visual>
    <origin xyz="0.181234 -0.458905 -0.07904" rpy="0 0 0"/>
    <geometry>
      <mesh filename="package://robot_description/meshes/wheel_v1_2.stl" scale="0.001 0.001 0.001"/>
    </geometry>
    <material name="rubber_soft"/>
  </visual>
  <collision>
    <origin xyz="0.181234 -0.458905 -0.07904" rpy="0 0 0"/>
    <geometry>
      <mesh filename="package://robot_description/meshes/wheel_v1_2.stl" scale="0.001 0.001 0.001"/>
    </geometry>
  </collision>
</link>

<link name="wheel_v1_3">
  <inertial>
    <origin xyz="0.04953961517408048 8.440090276673473e-08 1.0399095619340049e-07" rpy="0 0 0"/>
    <mass value="0.6661433062671792"/>
    <inertia ixx="0.001849" iyy="0.001024" izz="0.001024" ixy="0.0" iyz="0.0" ixz="-0.0"/>
  </inertial>
  <visual>
    <origin xyz="-0.178766 -0.458905 -0.07904" rpy="0 0 0"/>
    <geometry>
      <mesh filename="package://robot_description/meshes/wheel_v1_3.stl" scale="0.001 0.001 0.001"/>
    </geometry>
    <material name="rubber_soft"/>
  </visual>
  <collision>
    <origin xyz="-0.178766 -0.458905 -0.07904" rpy="0 0 0"/>
    <geometry>
      <mesh filename="package://robot_description/meshes/wheel_v1_3.stl" scale="0.001 0.001 0.001"/>
    </geometry>
  </collision>
</link>

<link name="wheel_v1_4">
  <inertial>
    <origin xyz="0.049539615174083756 8.44009104272736e-08 1.0399095512481082e-07" rpy="0 0 0"/>
    <mass value="0.6661433062671792"/>
    <inertia ixx="0.001849" iyy="0.001024" izz="0.001024" ixy="0.0" iyz="-0.0" ixz="-0.0"/>
  </inertial>
  <visual>
    <origin xyz="-0.178766 0.461095 -0.07904" rpy="0 0 0"/>
    <geometry>
      <mesh filename="package://robot_description/meshes/wheel_v1_4.stl" scale="0.001 0.001 0.001"/>
    </geometry>
    <material name="rubber_soft"/>
  </visual>
  <collision>
    <origin xyz="-0.178766 0.461095 -0.07904" rpy="0 0 0"/>
    <geometry>
      <mesh filename="package://robot_description/meshes/wheel_v1_4.stl" scale="0.001 0.001 0.001"/>
    </geometry>
  </collision>
</link>

<joint name="Rigid 1" type="fixed">
  <origin xyz="-0.001234 -0.001095 0.229789" rpy="0 0 0"/>
  <parent link="base_link"/>
  <child link="base_top_1"/>
</joint>

<joint name="Rigid 3" type="fixed">
  <origin xyz="0.0 0.25 0.04" rpy="0 0 0"/>
  <parent link="base_top_1"/>
  <child link="camera_1"/>
</joint>

<joint name="Rigid 5" type="fixed">
  <origin xyz="0.0 -0.25 0.04" rpy="0 0 0"/>
  <parent link="base_top_1"/>
  <child link="lidar_1"/>
</joint>

<joint name="Revolute 6" type="continuous">
  <origin xyz="-0.231234 0.458905 0.229789" rpy="0 0 0"/>
  <parent link="base_link"/>
  <child link="azimuth_v1_1"/>
  <axis xyz="-0.0 -0.0 -1.0"/>
</joint>

<joint name="Revolute 7" type="continuous">
  <origin xyz="-0.231234 -0.461095 0.229789" rpy="0 0 0"/>
  <parent link="base_link"/>
  <child link="azimuth_v1_2"/>
  <axis xyz="-0.0 -0.0 -1.0"/>
</joint>

<joint name="Revolute 8" type="continuous">
  <origin xyz="0.228766 0.458905 0.229789" rpy="0 0 0"/>
  <parent link="base_link"/>
  <child link="azimuth_v1_3"/>
  <axis xyz="-0.0 -0.0 -1.0"/>
</joint>

<joint name="Revolute 9" type="continuous">
  <origin xyz="0.228766 -0.461095 0.229789" rpy="0 0 0"/>
  <parent link="base_link"/>
  <child link="azimuth_v1_4"/>
  <axis xyz="-0.0 -0.0 -1.0"/>
</joint>

<joint name="Revolute 10" type="continuous">
  <origin xyz="0.05 0.0 -0.150749" rpy="0 0 0"/>
  <parent link="azimuth_v1_2"/>
  <child link="wheel_v1_1"/>
  <axis xyz="-1.0 0.0 0.0"/>
</joint>

<joint name="Revolute 11" type="continuous">
  <origin xyz="0.05 0.0 -0.150749" rpy="0 0 0"/>
  <parent link="azimuth_v1_1"/>
  <child link="wheel_v1_2"/>
  <axis xyz="-1.0 0.0 0.0"/>
</joint>

<joint name="Revolute 12" type="continuous">
  <origin xyz="-0.05 0.0 -0.150749" rpy="0 0 0"/>
  <parent link="azimuth_v1_3"/>
  <child link="wheel_v1_3"/>
  <axis xyz="1.0 -0.0 -0.0"/>
</joint>

<joint name="Revolute 13" type="continuous">
  <origin xyz="-0.05 0.0 -0.150749" rpy="0 0 0"/>
  <parent link="azimuth_v1_4"/>
  <child link="wheel_v1_4"/>
  <axis xyz="1.0 -0.0 -0.0"/>
</joint>

</robot>
